Workbook

Sheet Inputs
A1: ULTRAFAN NEO PROGRAMME - MODEL INPUTS
A3: 1. Project Fundamentals
A4: Start Year | B4: 2026
A5: Forecast Horizon (Years) | B5: 7
A6: Perpetual Growth Rate (g) | B6: 0.025
A7: Corporate Tax Rate | B7: 0.25
A9: 2. CAPEX & Depreciation
A10: Year 0 CAPEX (£) | B10: 2500000000
A11: Sustaining CAPEX (Years 1-7) (£) | B11: 55000000
A12: Asset Useful Life (Years) | B12: 12
A14: 3. Engine Revenues
A15: Engine List Price (£) | B15: 13500000
A16: Year 3 Unit Sales | B16: 25
A17: Year 7 Unit Sales | B17: 95
A18: Market Share Capture (%) | B18: 0.12
A19: Aftermarket £/Engine-Year | B19: 425000
A21: 4. Operating Costs
A22: Unit COGS - Early Years (£) | B22: 11200000
A23: Unit COGS - Mature Years (£) | B23: 8900000
A24: Certification Costs Year 1 (£) | B24: 275000000
A25: Certification Costs Year 2 (£) | B25: 180000000
A26: Annual Programme Mgmt Cost (£) | B26: 65000000
A27: Aftermarket COGS Margin (%) | B27: 0.38
A29: 5. Working Capital
A30: NWC as % of Revenue | B30: 0.18
A32: 6. Financing Inputs
A33: WACC (Bloomberg) | B33: 0.113
A34: Cost of Equity | B34: 0.1166
A35: Cost of Debt | B35: 0.0443
A36: Adjusted Beta | B36: 1.011
A37: Risk-Free Rate | B37: 0.0443
A38: Market Risk Premium | B38: 0.0723
A39: Project Debt as % of CAPEX | B39: 0.06
A40: Project Debt Amount (£) | B40: =B10*B39 -> 150000000
A41: Amortization | B41: None (level debt)
A42: Equity Weight (%) | B42: 0.944
A43: Debt Weight (%) | B43: 0.056
A47: Year 4 Unit Sales | B47: 45
A48: Year 5 Unit Sales | B48: 65
A49: Year 6 Unit Sales | B49: 80
...

Sheet Revenue_Forecast
A1: REVENUE FORECAST
A2: Year | B2: 0 | C2: 1 | D2: 2 | E2: 3 | F2: 4 | G2: 5 | H2: 6 | I2: 7
A3: Engine Unit Sales | B3: 0 | C3: 0 | D3: 0 | E3: =Inputs!B16 -> 25 | F3: =Inputs!B47 -> 45 | G3: =Inputs!B48 -> 65 | H3: =Inputs!B49 -> 80 | I3: =Inputs!B17 -> 95
A4: OE Revenue (£) | B4: =B3*Inputs!$B$15 -> 0 | C4: =C3*Inputs!$B$15 -> 0 | D4: =D3*Inputs!$B$15 -> 0 | E4: =E3*Inputs!$B$15 -> 337500000 | F4: =F3*Inputs!$B$15 -> 607500000 | G4: =G3*Inputs!$B$15 -> 877500000 | H4: =H3*Inputs!$B$15 -> 1080000000 | I4: =I3*Inputs!$B$15 -> 1282500000
A5: Cumulative Engines in Service | B5: 0 | C5: =B3 -> 0 | D5: =C5+C3 -> 0 | E5: =D5+D3 -> 0 | F5: =E5+E3 -> 25 | G5: =F5+F3 -> 70 | H5: =G5+G3 -> 135 | I5: =H5+H3 -> 215
A6: Aftermarket Revenue (£) | B6: 0 | C6: 0 | D6: 0 | E6: 0 | F6: =F5*Inputs!$B$19 -> 10625000 | G6: =G5*Inputs!$B$19 -> 29750000 | H6: =H5*Inputs!$B$19 -> 57375000 | I6: =I5*Inputs!$B$19 -> 91375000
A7: Cannibalised Units | B7: 0 | C7: 0 | D7: 0 | E7: =E3*Inputs!$B$51 -> 3.75 | F7: =F3*Inputs!$B$52 -> 8.1 | G7: =G3*Inputs!$B$53 -> 13 | H7: =H3*Inputs!$B$54 -> 17.6 | I7: =I3*Inputs!$B$55 -> 23.75
A8: Lost Contribution Margin (£) | B8: =B7*Inputs!$B$50 -> 0 | C8: =C7*Inputs!$B$50 -> 0 | D8: =D7*Inputs!$B$50 -> 0 | E8: =E7*Inputs!$B$50 -> 12000000 | F8: =F7*Inputs!$B$50 -> 25920000 | G8: =G7*Inputs!$B$50 -> 41600000 | H8: =H7*Inputs!$B$50 -> 56320000 | I8: =I7*Inputs!$B$50 -> 76000000
A9: Net Incremental Revenue (£) | B9: =B4+B6-B8 -> 0 | C9: =C4+C6-C8 -> 0 | D9: =D4+D6-D8 -> 0 | E9: =E4+E6-E8 -> 325500000 | F9: =F4+F6-F8 -> 592205000 | G9: =G4+G6-G8 -> 865650000 | H9: =H4+H6-H8 -> 1081055000 | I9: =I4+I6-I8 -> 1297875000

Sheet Operating_Costs
A1: OPERATING COSTS
A2: Year | B2: 0 | C2: 1 | D2: 2 | E2: 3 | F2: 4 | G2: 5 | H2: 6 | I2: 7
A3: Production COGS (£) | B3: 0 | C3: 0 | D3: 0 | E3: =Revenue_Forecast!E3*Inputs!$B$22 -> 280000000 | F3: =Revenue_Forecast!F3*Inputs!$B$22 -> 504000000 | G3: =Revenue_Forecast!G3*Inputs!$B$23 -> 578500000 | H3: =Revenue_Forecast!H3*Inputs!$B$23 -> 712000000 | I3: =Revenue_Forecast!I3*Inputs!$B$23 -> 845500000
A4: Certification Costs (£) | B4: 0 | C4: =Inputs!$B$24 -> 275000000 | D4: =Inputs!$B$25 -> 180000000 | E4: 0 | F4: 0 | G4: 0 | H4: 0 | I4: 0
A5: Programme Management (£) | B5: 0 | C5: =Inputs!$B$26 -> 65000000 | D5: =Inputs!$B$26 -> 65000000 | E5: =Inputs!$B$26 -> 65000000 | F5: =Inputs!$B$26 -> 65000000 | G5: =Inputs!$B$26 -> 65000000 | H5: =Inputs!$B$26 -> 65000000 | I5: =Inputs!$B$26 -> 65000000
A6: Aftermarket Service COGS (£) | B6: =Revenue_Forecast!B6*Inputs!$B$27 -> 0 | C6: =Revenue_Forecast!C6*Inputs!$B$27 -> 0 | D6: =Revenue_Forecast!D6*Inputs!$B$27 -> 0 | E6: =Revenue_Forecast!E6*Inputs!$B$27 -> 0 | F6: =Revenue_Forecast!F6*Inputs!$B$27 -> 4037500 | G6: =Revenue_Forecast!G6*Inputs!$B$27 -> 11305000 | H6: =Revenue_Forecast!H6*Inputs!$B$27 -> 21802500 | I6: =Revenue_Forecast!I6*Inputs!$B$27 -> 34722500
A7: Facility Opportunity Cost (£) | B7: 0 | C7: =Inputs!$B$56 -> 28000000 | D7: =Inputs!$B$56 -> 28000000 | E7: =Inputs!$B$56 -> 28000000 | F7: =Inputs!$B$56 -> 28000000 | G7: =Inputs!$B$56 -> 28000000 | H7: =Inputs!$B$56 -> 28000000 | I7: =Inputs!$B$56 -> 28000000
A8: Total Operating Costs (£) | B8: =B3+B4+B5+B6+B7 -> 0 | C8: =C3+C4+C5+C6+C7 -> 368000000 | D8: =D3+D4+D5+D6+D7 -> 273000000 | E8: =E3+E4+E5+E6+E7 -> 373000000 | F8: =F3+F4+F5+F6+F7 -> 601037500 | G8: =G3+G4+G5+G6+G7 -> 682805000 | H8: =H3+H4+H5+H6+H7 -> 826802500 | I8: =I3+I4+I5+I6+I7 -> 973222500

Sheet EBITDA_EBIT
A1: EBITDA & EBIT CALCULATION
A2: Year | B2: 0 | C2: 1 | D2: 2 | E2: 3 | F2: 4 | G2: 5 | H2: 6 | I2: 7
A3: Net Incremental Revenue (GBP m) | B3: =Revenue_Forecast!B9/1000000 -> 0 | C3: =Revenue_Forecast!C9/1000000 -> 0 | D3: =Revenue_Forecast!D9/1000000 -> 0 | E3: =Revenue_Forecast!E9/1000000 -> 325.5 | F3: =Revenue_Forecast!F9/1000000 -> 592.205 | G3: =Revenue_Forecast!G9/1000000 -> 865.65 | H3: =Revenue_Forecast!H9/1000000 -> 1081.055 | I3: =Revenue_Forecast!I9/1000000 -> 1297.875
A4: Total Operating Costs (GBP m) | B4: =Operating_Costs!B8/1000000 -> 0 | C4: =Operating_Costs!C8/1000000 -> 368 | D4: =Operating_Costs!D8/1000000 -> 273 | E4: =Operating_Costs!E8/1000000 -> 373 | F4: =Operating_Costs!F8/1000000 -> 601.0375 | G4: =Operating_Costs!G8/1000000 -> 682.805 | H4: =Operating_Costs!H8/1000000 -> 826.8025 | I4: =Operating_Costs!I8/1000000 -> 973.2225
A5: EBITDA (GBP m) | B5: =B3-B4 -> 0 | C5: =C3-C4 -> -368 | D5: =D3-D4 -> -273 | E5: =E3-E4 -> -47.5 | F5: =F3-F4 -> -8.8325 | G5: =G3-G4 -> 182.845 | H5: =H3-H4 -> 254.2525 | I5: =I3-I4 -> 324.6525
A6: Depreciation (GBP m) | B6: 0 | C6: =Inputs!$B$10/Inputs!$B$12/1000000 -> 208.33333 | D6: =Inputs!$B$10/Inputs!$B$12/1000000 -> 208.33333 | E6: =Inputs!$B$10/Inputs!$B$12/1000000 -> 208.33333 | F6: =Inputs!$B$10/Inputs!$B$12/1000000 -> 208.33333 | G6: =Inputs!$B$10/Inputs!$B$12/1000000 -> 208.33333 | H6: =Inputs!$B$10/Inputs!$B$12/1000000 -> 208.33333 | I6: =Inputs!$B$10/Inputs!$B$12/1000000 -> 208.33333
A7: EBIT (GBP m) | B7: =B5-B6 -> 0 | C7: =C5-C6 -> -576.33333 | D7: =D5-D6 -> -481.33333 | E7: =E5-E6 -> -255.83333 | F7: =F5-F6 -> -217.16583 | G7: =G5-G6 -> -25.488333 | H7: =H5-H6 -> 45.919167 | I7: =I5-I6 -> 116.31917

Sheet Working_Capital
A1: WORKING CAPITAL
A2: Year | B2: 0 | C2: 1 | D2: 2 | E2: 3 | F2: 4 | G2: 5 | H2: 6 | I2: 7
A3: Net Incremental Revenue (GBP m) | B3: =Revenue_Forecast!B9/1000000 -> 0 | C3: =Revenue_Forecast!C9/1000000 -> 0 | D3: =Revenue_Forecast!D9/1000000 -> 0 | E3: =Revenue_Forecast!E9/1000000 -> 325.5 | F3: =Revenue_Forecast!F9/1000000 -> 592.205 | G3: =Revenue_Forecast!G9/1000000 -> 865.65 | H3: =Revenue_Forecast!H9/1000000 -> 1081.055 | I3: =Revenue_Forecast!I9/1000000 -> 1297.875
A4: NWC as % of Revenue | B4: =Inputs!$B$30 -> 0.18 | C4: =Inputs!$B$30 -> 0.18 | D4: =Inputs!$B$30 -> 0.18 | E4: =Inputs!$B$30 -> 0.18 | F4: =Inputs!$B$30 -> 0.18 | G4: =Inputs!$B$30 -> 0.18 | H4: =Inputs!$B$30 -> 0.18 | I4: =Inputs!$B$30 -> 0.18
A5: NWC Level (GBP m) | B5: =B3*B4 -> 0 | C5: =C3*C4 -> 0 | D5: =D3*D4 -> 0 | E5: =E3*E4 -> 58.59 | F5: =F3*F4 -> 106.5969 | G5: =G3*G4 -> 155.817 | H5: =H3*H4 -> 194.5899 | I5: =I3*I4 -> 233.6175
A6: Delta NWC (GBP m) | B6: 0 | C6: =C5-B5 -> 0 | D6: =D5-C5 -> 0 | E6: =E5-D5 -> 58.59 | F6: =F5-E5 -> 48.0069 | G6: =G5-F5 -> 49.2201 | H6: =H5-G5 -> 38.7729 | I6: =I5-H5 -> 39.0276

Sheet FCFF
A1: FREE CASH FLOW TO FIRM (FCFF)
A2: Year | B2: 0 | C2: 1 | D2: 2 | E2: 3 | F2: 4 | G2: 5 | H2: 6 | I2: 7
A3: EBIT (GBP m) | B3: =EBITDA_EBIT!B7 -> 0 | C3: =EBITDA_EBIT!C7 -> -576.33333 | D3: =EBITDA_EBIT!D7 -> -481.33333 | E3: =EBITDA_EBIT!E7 -> -255.83333 | F3: =EBITDA_EBIT!F7 -> -217.16583 | G3: =EBITDA_EBIT!G7 -> -25.488333 | H3: =EBITDA_EBIT!H7 -> 45.919167 | I3: =EBITDA_EBIT!I7 -> 116.31917
A4: Tax on EBIT (GBP m) | B4: =B3*Inputs!$B$7 -> 0 | C4: =C3*Inputs!$B$7 -> -144.08333 | D4: =D3*Inputs!$B$7 -> -120.33333 | E4: =E3*Inputs!$B$7 -> -63.958333 | F4: =F3*Inputs!$B$7 -> -54.291458 | G4: =G3*Inputs!$B$7 -> -6.3720833 | H4: =H3*Inputs!$B$7 -> 11.479792 | I4: =I3*Inputs!$B$7 -> 29.079792
A5: NOPAT (GBP m) | B5: =B3-B4 -> 0 | C5: =C3-C4 -> -432.25 | D5: =D3-D4 -> -361 | E5: =E3-E4 -> -191.875 | F5: =F3-F4 -> -162.87437 | G5: =G3-G4 -> -19.11625 | H5: =H3-H4 -> 34.439375 | I5: =I3-I4 -> 87.239375
A6: Add: Depreciation (GBP m) | B6: =EBITDA_EBIT!B6 -> 0 | C6: =EBITDA_EBIT!C6 -> 208.33333 | D6: =EBITDA_EBIT!D6 -> 208.33333 | E6: =EBITDA_EBIT!E6 -> 208.33333 | F6: =EBITDA_EBIT!F6 -> 208.33333 | G6: =EBITDA_EBIT!G6 -> 208.33333 | H6: =EBITDA_EBIT!H6 -> 208.33333 | I6: =EBITDA_EBIT!I6 -> 208.33333
A7: Less: CAPEX (GBP m) | B7: =-Inputs!B10/1000000 -> -2500 | C7: =-Inputs!B11/1000000 -> -55 | D7: =-Inputs!B11/1000000 -> -55 | E7: =-Inputs!B11/1000000 -> -55 | F7: =-Inputs!B11/1000000 -> -55 | G7: =-Inputs!B11/1000000 -> -55 | H7: =-Inputs!B11/1000000 -> -55 | I7: =-Inputs!B11/1000000 -> -55
A8: Less: Delta NWC (GBP m) | B8: =Working_Capital!B6 -> 0 | C8: =Working_Capital!C6 -> 0 | D8: =Working_Capital!D6 -> 0 | E8: =Working_Capital!E6 -> 58.59 | F8: =Working_Capital!F6 -> 48.0069 | G8: =Working_Capital!G6 -> 49.2201 | H8: =Working_Capital!H6 -> 38.7729 | I8: =Working_Capital!I6 -> 39.0276
A9: FCFF (GBP m) | B9: =B5+B6+B7-B8 -> -2500 | C9: =C5+C6+C7-C8 -> -278.91667 | D9: =D5+D6+D7-D8 -> -207.66667 | E9: =E5+E6+E7-E8 -> -97.131667 | F9: =F5+F6+F7-F8 -> -57.547942 | G9: =G5+G6+G7-G8 -> 84.996983 | H9: =H5+H6+H7-H8 -> 148.99981 | I9: =I5+I6+I7-I8 -> 201.54511

Sheet WACC_Valuation
A1: WACC METHOD VALUATION
A2: Year | B2: 0 | C2: 1 | D2: 2 | E2: 3 | F2: 4 | G2: 5 | H2: 6 | I2: 7
A3: FCFF (GBP m) | B3: =FCFF!B9 -> -2500 | C3: =FCFF!C9 -> -278.91667 | D3: =FCFF!D9 -> -207.66667 | E3: =FCFF!E9 -> -97.131667 | F3: =FCFF!F9 -> -57.547942 | G3: =FCFF!G9 -> 84.996983 | H3: =FCFF!H9 -> 148.99981 | I3: =FCFF!I9 -> 201.54511
A4: Discount Factor (WACC) | B4: =1/((1+Inputs!$B$33)^0) -> 1 | C4: =1/((1+Inputs!$B$33)^1) -> 0.8984726 | D4: =1/((1+Inputs!$B$33)^2) -> 0.80725301 | E4: =1/((1+Inputs!$B$33)^3) -> 0.72529471 | F4: =1/((1+Inputs!$B$33)^4) -> 0.65165742 | G4: =1/((1+Inputs!$B$33)^5) -> 0.58549633 | H4: =1/((1+Inputs!$B$33)^6) -> 0.52605241 | I4: =1/((1+Inputs!$B$33)^7) -> 0.47264367
A5: PV of FCFF (GBP m) | B5: =B3*B4 -> -2500 | C5: =C3*C4 -> -250.59898 | D5: =D3*D4 -> -167.63954 | E5: =E3*E4 -> -70.449084 | F5: =F3*F4 -> -37.501543 | G5: =G3*G4 -> 49.765422 | H5: =H3*H4 -> 78.381708 | I5: =I3*I4 -> 95.259021
A7: Terminal Value (GBP m) | I7: =I3*(1+Inputs!$B$6)/(Inputs!$B$33-Inputs!$B$6) -> 2347.5425
A8: PV of Terminal Value (GBP m) | I8: =I7*I4 -> 1109.5511
A10: Sum of PV(FCFF) Years 0-7 (GBP m) | B10: =SUM(B5:I5) -> -2802.783
A11: PV of Terminal Value (GBP m) | B11: =I8 -> 1109.5511
A13: Enterprise Value (WACC Method) (GBP m) | B13: =B10+B11 -> -1693.2319
A15: NPV (WACC Method) (GBP m) | B15: =B13 -> -1693.2319

Sheet APV_Valuation
A1: APV METHOD VALUATION
A2: Year | B2: 0 | C2: 1 | D2: 2 | E2: 3 | F2: 4 | G2: 5 | H2: 6 | I2: 7
A3: SECTION A: UNLEVERED PROJECT VALUE
A4: Unlevered Cost of Capital (r_u) | B4: =Inputs!$B$33+(Inputs!$B$43*Inputs!$B$35*Inputs!$B$7) -> 0.1136202
A5: FCFF (GBP m) | B5: =FCFF!B9 -> -2500 | C5: =FCFF!C9 -> -278.91667 | D5: =FCFF!D9 -> -207.66667 | E5: =FCFF!E9 -> -97.131667 | F5: =FCFF!F9 -> -57.547942 | G5: =FCFF!G9 -> 84.996983 | H5: =FCFF!H9 -> 148.99981 | I5: =FCFF!I9 -> 201.54511
A6: Discount Factor (r_u) | B6: =1/((1+$B$4)^0) -> 1 | C6: =1/((1+$B$4)^1) -> 0.89797222 | D6: =1/((1+$B$4)^2) -> 0.8063541 | E6: =1/((1+$B$4)^3) -> 0.72408358 | F6: =1/((1+$B$4)^4) -> 0.65020694 | G6: =1/((1+$B$4)^5) -> 0.58386777 | H6: =1/((1+$B$4)^6) -> 0.52429703 | I6: =1/((1+$B$4)^7) -> 0.47080417
A7: PV of Unlevered FCFF (GBP m) | B7: =B5*B6 -> -2500 | C7: =C5*C6 -> -250.45942 | D7: =D5*D6 -> -167.45287 | E7: =E5*E6 -> -70.331445 | F7: =F5*F6 -> -37.418071 | G7: =G5*G6 -> 49.626999 | H7: =H5*H6 -> 78.120157 | I7: =I5*I6 -> 94.888277
A9: Unlevered Terminal Value (GBP m) | I9: =I5*(1+Inputs!$B$6)/($B$4-Inputs!$B$6) -> 2331.1134
A10: PV of Unlevered TV (GBP m) | I10: =I9*I6 -> 1097.4979
A12: Total Unlevered Project Value (GBP m) | B12: =SUM(B7:I7)+I10 -> -1705.5285
A14: SECTION B: PV OF INTEREST TAX SHIELD
A15: Debt Outstanding (GBP m) | B15: =Inputs!$B$40/1000000 -> 150 | C15: =Inputs!$B$40/1000000 -> 150 | D15: =Inputs!$B$40/1000000 -> 150 | E15: =Inputs!$B$40/1000000 -> 150 | F15: =Inputs!$B$40/1000000 -> 150 | G15: =Inputs!$B$40/1000000 -> 150 | H15: =Inputs!$B$40/1000000 -> 150 | I15: =Inputs!$B$40/1000000 -> 150
A16: Interest Expense (GBP m) | B16: 0 | C16: =C15*Inputs!$B$35 -> 6.645 | D16: =D15*Inputs!$B$35 -> 6.645 | E16: =E15*Inputs!$B$35 -> 6.645 | F16: =F15*Inputs!$B$35 -> 6.645 | G16: =G15*Inputs!$B$35 -> 6.645 | H16: =H15*Inputs!$B$35 -> 6.645 | I16: =I15*Inputs!$B$35 -> 6.645
A17: Tax Shield (GBP m) | B17: =B16*Inputs!$B$7 -> 0 | C17: =C16*Inputs!$B$7 -> 1.66125 | D17: =D16*Inputs!$B$7 -> 1.66125 | E17: =E16*Inputs!$B$7 -> 1.66125 | F17: =F16*Inputs!$B$7 -> 1.66125 | G17: =G16*Inputs!$B$7 -> 1.66125 | H17: =H16*Inputs!$B$7 -> 1.66125 | I17: =I16*Inputs!$B$7 -> 1.66125
A18: Discount Factor (r_d) | B18: =1/((1+Inputs!$B$35)^0) -> 1 | C18: =1/((1+Inputs!$B$35)^1) -> 0.95757924 | D18: =1/((1+Inputs!$B$35)^2) -> 0.916958 | E18: =1/((1+Inputs!$B$35)^3) -> 0.87805994 | F18: =1/((1+Inputs!$B$35)^4) -> 0.84081197 | G18: =1/((1+Inputs!$B$35)^5) -> 0.80514409 | H18: =1/((1+Inputs!$B$35)^6) -> 0.77098927 | I18: =1/((1+Inputs!$B$35)^7) -> 0.73828332
A19: PV of Tax Shield (GBP m) | B19: =B17*B18 -> 0 | C19: =C17*C18 -> 1.5907785 | D19: =D17*D18 -> 1.5232965 | E19: =E17*E18 -> 1.4586771 | F19: =F17*F18 -> 1.3967989 | G19: =G17*G18 -> 1.3375456 | H19: =H17*H18 -> 1.2808059 | I19: =I17*I18 -> 1.2264732
A21: Total PV of Tax Shield (GBP m) | B21: =SUM(B19:I19) -> 9.8143757
A23: SECTION C: APV & NPV
A24: Adjusted Present Value (APV) (GBP m) | B24: =B12+B21 -> -1695.7141
A26: NPV (APV Method) (GBP m) | B26: =B24 -> -1695.7141

Sheet FCFE_Valuation
A1: FCFE METHOD VALUATION
A2: Year | B2: 0 | C2: 1 | D2: 2 | E2: 3 | F2: 4 | G2: 5 | H2: 6 | I2: 7
A3: SECTION A: BUILD FCFE
A4: FCFF (GBP m) | B4: =FCFF!B9 -> -2500 | C4: =FCFF!C9 -> -278.91667 | D4: =FCFF!D9 -> -207.66667 | E4: =FCFF!E9 -> -97.131667 | F4: =FCFF!F9 -> -57.547942 | G4: =FCFF!G9 -> 84.996983 | H4: =FCFF!H9 -> 148.99981 | I4: =FCFF!I9 -> 201.54511
A5: Interest Expense (GBP m) | B5: 0 | C5: =(Inputs!$B$40/1000000)*Inputs!$B$35 -> 6.645 | D5: =(Inputs!$B$40/1000000)*Inputs!$B$35 -> 6.645 | E5: =(Inputs!$B$40/1000000)*Inputs!$B$35 -> 6.645 | F5: =(Inputs!$B$40/1000000)*Inputs!$B$35 -> 6.645 | G5: =(Inputs!$B$40/1000000)*Inputs!$B$35 -> 6.645 | H5: =(Inputs!$B$40/1000000)*Inputs!$B$35 -> 6.645 | I5: =(Inputs!$B$40/1000000)*Inputs!$B$35 -> 6.645
A6: After-tax Interest (GBP m) | B6: =B5*(1-Inputs!$B$7) -> 0 | C6: =C5*(1-Inputs!$B$7) -> 4.98375 | D6: =D5*(1-Inputs!$B$7) -> 4.98375 | E6: =E5*(1-Inputs!$B$7) -> 4.98375 | F6: =F5*(1-Inputs!$B$7) -> 4.98375 | G6: =G5*(1-Inputs!$B$7) -> 4.98375 | H6: =H5*(1-Inputs!$B$7) -> 4.98375 | I6: =I5*(1-Inputs!$B$7) -> 4.98375
A7: Net Borrowing (GBP m) | B7: =Inputs!$B$40/1000000 -> 150 | C7: 0 | D7: 0 | E7: 0 | F7: 0 | G7: 0 | H7: 0 | I7: 0
A8: FCFE (GBP m) | B8: =B4-B6+B7 -> -2350 | C8: =C4-C6+C7 -> -283.90042 | D8: =D4-D6+D7 -> -212.65042 | E8: =E4-E6+E7 -> -102.11542 | F8: =F4-F6+F7 -> -62.531692 | G8: =G4-G6+G7 -> 80.013233 | H8: =H4-H6+H7 -> 144.01606 | I8: =I4-I6+I7 -> 196.56136
A10: SECTION B: DISCOUNT & VALUE EQUITY
A11: Cost of Equity (r_e) | B11: =Inputs!$B$34 -> 0.1166
A12: Discount Factor (r_e) | B12: =1/((1+$B$11)^0) -> 1 | C12: =1/((1+$B$11)^1) -> 0.89557586 | D12: =1/((1+$B$11)^2) -> 0.80205611 | E12: =1/((1+$B$11)^3) -> 0.71830209 | F12: =1/((1+$B$11)^4) -> 0.64329401 | G12: =1/((1+$B$11)^5) -> 0.57611858 | H12: =1/((1+$B$11)^6) -> 0.51595789 | I12: =1/((1+$B$11)^7) -> 0.46207943
A13: PV of FCFE (GBP m) | B13: =B8*B12 -> -2350 | C13: =C8*C12 -> -254.25436 | D13: =D8*D12 -> -170.55757 | E13: =E8*E12 -> -73.349717 | F13: =F8*F12 -> -40.226263 | G13: =G8*G12 -> 46.09711 | H13: =H8*H12 -> 74.306222 | I13: =I8*I12 -> 90.82696
A15: Equity Terminal Value (GBP m) | I15: =I8*(1+Inputs!$B$6)/($B$11-Inputs!$B$6) -> 2199.513
A16: PV of Equity TV (GBP m) | I16: =I15*I12 -> 1016.3497
A18: Equity Value (Gross) (GBP m) | B18: =SUM(C13:I13)+I16 -> 689.19211
A19: Equity Investment (Initial) (GBP m) | B19: =-B8 -> 2350
A21: NPV (FCFE Method) (GBP m) | B21: =B18-B19 -> -1660.8079

Sheet Sensitivity_Analysis
A1: Sensitivity Analysis – UltraFan Neo (WACC & g)
B2: WACC sensitivity around Bloomberg WACC | E2: g sensitivity around base g
B3: WACC | C3: NPV (GBP m) | E3: g | F3: NPV (GBP m)
B4: 0.083 | C4: -749.85827 | E4: 0 | F4: -1959.7828
B5: 0.093 | C5: -1163.476 | E5: 0.01 | F5: -1868.6897
B6: 0.103 | C6: -1465.1111 | E6: 0.025 | F6: -1693.2319
B7: 0.113 | C7: -1693.2319 | E7: 0.03 | F7: -1620.653
B8: 0.123 | C8: -1870.5878 | E8: 0.04 | F8: -1445.6682
B9: 0.133 | C9: -2011.488
B10: 0.143 | C10: -2125.3788

Sheet Scenario_Analysis
A1: Scenario Analysis – UltraFan Neo
B3: Scenario | C3: Rev multiplier | D3: WACC shift (decimal) | E3: g shift (decimal)
B4: Best | C4: 1.2 | D4: -0.01 | E4: 0.005
B5: Base | C5: 1 | D5: 0 | E5: 0
B6: Worst | C6: 0.8 | D6: 0.01 | E6: -0.005
A8: Scenario | B8: WACC_s | C8: g_s | D8: NPV (GBP m) | E8: TV (GBP m) | F8: FCFF7 (GBP m)
A9: =B4 -> Best | B9: =Inputs!$B$33 + $D4 -> 0.103 | C9: =Inputs!$B$6 + $E4 -> 0.03 | D9: =NPV($B9,C16:I16)+B16+INDEX(B16:I16,1,8)*(1+$C9)/($B9-$C9)/(1+$B9)^7 -> -1640.1956 | E9: =INDEX(B16:I16,1,8)*(1+$C9)/($B9-$C9)/(1+$B9)^7 -> 1718.0638 | F9: =INDEX(B16:I16,1,8) -> 241.85413
A10: =B5 -> Base | B10: =Inputs!$B$33 + $D5 -> 0.113 | C10: =Inputs!$B$6 + $E5 -> 0.025 | D10: =NPV($B10,C17:I17)+B17+INDEX(B17:I17,1,8)*(1+$C10)/($B10-$C10)/(1+$B10)^7 -> -1693.2319 | E10: =INDEX(B17:I17,1,8)*(1+$C10)/($B10-$C10)/(1+$B10)^7 -> 1109.5511 | F10: =INDEX(B17:I17,1,8) -> 201.54511
A11: =B6 -> Worst | B11: =Inputs!$B$33 + $D6 -> 0.123 | C11: =Inputs!$B$6 + $E6 -> 0.02 | D11: =NPV($B11,C18:I18)+B18+INDEX(B18:I18,1,8)*(1+$C11)/($B11-$C11)/(1+$B11)^7 -> -1536.2893 | E11: =INDEX(B18:I18,1,8)*(1+$C11)/($B11-$C11)/(1+$B11)^7 -> 708.8705 | F11: =INDEX(B18:I18,1,8) -> 161.23609
A15: Base FCFF (GBP m) | B15: =FCFF!B9 -> -2500 | C15: =FCFF!C9 -> -278.91667 | D15: =FCFF!D9 -> -207.66667 | E15: =FCFF!E9 -> -97.131667 | F15: =FCFF!F9 -> -57.547942 | G15: =FCFF!G9 -> 84.996983 | H15: =FCFF!H9 -> 148.99981 | I15: =FCFF!I9 -> 201.54511
A16: Best FCFF | B16: =B15*$C$4 -> -3000 | C16: =C15*$C$4 -> -334.7 | D16: =D15*$C$4 -> -249.2 | E16: =E15*$C$4 -> -116.558 | F16: =F15*$C$4 -> -69.05753 | G16: =G15*$C$4 -> 101.99638 | H16: =H15*$C$4 -> 178.79977 | I16: =I15*$C$4 -> 241.85413
A17: Base FCFF | B17: =B15*$C$5 -> -2500 | C17: =C15*$C$5 -> -278.91667 | D17: =D15*$C$5 -> -207.66667 | E17: =E15*$C$5 -> -97.131667 | F17: =F15*$C$5 -> -57.547942 | G17: =G15*$C$5 -> 84.996983 | H17: =H15*$C$5 -> 148.99981 | I17: =I15*$C$5 -> 201.54511
A18: Worst FCFF | B18: =B15*$C$6 -> -2000 | C18: =C15*$C$6 -> -223.13333 | D18: =D15*$C$6 -> -166.13333 | E18: =E15*$C$6 -> -77.705333 | F18: =F15*$C$6 -> -46.038353 | G18: =G15*$C$6 -> 67.997587 | H18: =H15*$C$6 -> 119.19985 | I18: =I15*$C$6 -> 161.23609

Sheet Breakeven_Analysis
A1: Breakeven Analysis – UltraFan Neo
A3: Base Year-3 net incremental revenue (GBP) | B3: =Revenue_Forecast!$E$9 -> 325500000
A4: Trial Year-3 net incremental revenue (GBP) | B4: 1.4901161e-08
A5: Revenue scale factor | B5: =B4/B3 -> 0
A9: Scaled FCFF (GBP m) | B9: =FCFF!B9*$B$5 -> 0 | C9: =FCFF!C9*$B$5 -> 0 | D9: =FCFF!D9*$B$5 -> 0 | E9: =FCFF!E9*$B$5 -> 0 | F9: =FCFF!F9*$B$5 -> 0 | G9: =FCFF!G9*$B$5 -> 0 | H9: =FCFF!H9*$B$5 -> 0 | I9: =FCFF!I9*$B$5 -> 0
A11: NPV at this revenue (GBP m) | B11: {=NPV(Inputs!$B$33,C9:I9)+B9+INDEX(B9:I9,1,8)*(1+Inputs!$B$6)/(Inputs!$B$33-Inputs!$B$6)/(1+Inputs!$B$33)^7} -> 0
A14: Use Data → What-If Analysis → Goal Seek:
A15: Set cell B11 to 0 by changing cell B4.

Sheet MonteCarlo
A1: Monte Carlo Simulation – UltraFan Neo
A3: Base WACC | B3: =Inputs!$B$33 -> 0.113
A4: WACC min | B4: =B3-0.02 -> 0.093
A5: WACC max | B5: =B3+0.02 -> 0.133
A6: # simulations | B6: 10000
A8: Summary
A9: Mean NPV (GBP m) | B9: =AVERAGE(C14:C10013) -> -1657.6449
A10: Std Dev NPV (GBP m) | B10: =_xlfn.STDEV.S(C14:C10013) -> 241.10409
A11: Prob(NPV < 0) | B11: =COUNTIF(C14:C10013,"<0")/ROWS(C14:C10013) -> 1
A13: Iteration | B13: Random WACC | C13: NPV (GBP m)
A14: 1 | B14: =$B$4 + RAND()*($B$5-$B$4) -> 0.10569925 | C14: {=NPV(B14,FCFF!$C$9:$I$9)+FCFF!$B$9+FCFF!$I$9*(1+Inputs!$B$6)/(B14-Inputs!$B$6)/(1+B14)^7} -> -1532.7776
A15: 2 | B15: =$B$4 + RAND()*($B$5-$B$4) -> 0.11281884 | C15: {=NPV(B15,FCFF!$C$9:$I$9)+FCFF!$B$9+FCFF!$I$9*(1+Inputs!$B$6)/(B15-Inputs!$B$6)/(1+B15)^7} -> -1689.6038
A16: 3 | B16: =$B$4 + RAND()*($B$5-$B$4) -> 0.10750995 | C16: {=NPV(B16,FCFF!$C$9:$I$9)+FCFF!$B$9+FCFF!$I$9*(1+Inputs!$B$6)/(B16-Inputs!$B$6)/(1+B16)^7} -> -1575.4751
A17: 4 | B17: =$B$4 + RAND()*($B$5-$B$4) -> 0.12337085 | C17: {=NPV(B17,FCFF!$C$9:$I$9)+FCFF!$B$9+FCFF!$I$9*(1+Inputs!$B$6)/(B17-Inputs!$B$6)/(1+B17)^7} -> -1876.394
A18: 5 | B18: =$B$4 + RAND()*($B$5-$B$4) -> 0.11855608 | C18: {=NPV(B18,FCFF!$C$9:$I$9)+FCFF!$B$9+FCFF!$I$9*(1+Inputs!$B$6)/(B18-Inputs!$B$6)/(1+B18)^7} -> -1796.9816
A19: 6 | B19: =$B$4 + RAND()*($B$5-$B$4) -> 0.11480131 | C19: {=NPV(B19,FCFF!$C$9:$I$9)+FCFF!$B$9+FCFF!$I$9*(1+Inputs!$B$6)/(B19-Inputs!$B$6)/(1+B19)^7} -> -1728.4277
A20: 7 | B20: =$B$4 + RAND()*($B$5-$B$4) -> 0.12883889 | C20: {=NPV(B20,FCFF!$C$9:$I$9)+FCFF!$B$9+FCFF!$I$9*(1+Inputs!$B$6)/(B20-Inputs!$B$6)/(1+B20)^7} -> -1956.5979
A21: 8 | B21: =$B$4 + RAND()*($B$5-$B$4) -> 0.12939374 | C21: {=NPV(B21,FCFF!$C$9:$I$9)+FCFF!$B$9+FCFF!$I$9*(1+Inputs!$B$6)/(B21-Inputs!$B$6)/(1+B21)^7} -> -1964.2056
A22: 9 | B22: =$B$4 + RAND()*($B$5-$B$4) -> 0.11995183 | C22: {=NPV(B22,FCFF!$C$9:$I$9)+FCFF!$B$9+FCFF!$I$9*(1+Inputs!$B$6)/(B22-Inputs!$B$6)/(1+B22)^7} -> -1820.9306
A23: 10 | B23: =$B$4 + RAND()*($B$5-$B$4) -> 0.099570445 | C23: {=NPV(B23,FCFF!$C$9:$I$9)+FCFF!$B$9+FCFF!$I$9*(1+Inputs!$B$6)/(B23-Inputs!$B$6)/(1+B23)^7} -> -1371.455
A24: 11 | B24: =$B$4 + RAND()*($B$5-$B$4) -> 0.11638013 | C24: {=NPV(B24,FCFF!$C$9:$I$9)+FCFF!$B$9+FCFF!$I$9*(1+Inputs!$B$6)/(B24-Inputs!$B$6)/(1+B24)^7} -> -1758.0158
A25: 12 | B25: =$B$4 + RAND()*($B$5-$B$4) -> 0.10309933 | C25: {=NPV(B25,FCFF!$C$9:$I$9)+FCFF!$B$9+FCFF!$I$9*(1+Inputs!$B$6)/(B25-Inputs!$B$6)/(1+B25)^7} -> -1467.6912
... A10013: 10000 | B10013: =$B$4 + RAND()*($B$5-$B$4) -> 0.097765164 | C10013: {=NPV(B10013,FCFF!$C$9:$I$9)+FCFF!$B$9+FCFF!$I$9*(1+Inputs!$B$6)/(B10013-Inputs!$B$6)/(1+B10013)^7} -> -1318.3206

Sheet Tornado_Analysis
A1: Tornado Sensitivity Analysis – UltraFan Neo
A3: Parameter | B3: Low | C3: Base | D3: High
A4: WACC | B4: =Inputs!$B$33-0.01 -> 0.103 | C4: =Inputs!$B$33 -> 0.113 | D4: =Inputs!$B$33+0.01 -> 0.123
A5: g | B5: =Inputs!$B$6-0.005 -> 0.02 | C5: =Inputs!$B$6 -> 0.025 | D5: =Inputs!$B$6+0.005 -> 0.03
A6: Rev Scale | B6: 0.9 | C6: 1 | D6: 1.1
A10: Parameter | B10: Low NPV (GBP m) | C10: High NPV (GBP m) | D10: Range (High - Low)
A11: WACC | B11: {=NPV($B$4,FCFF!$C$9:$I$9)+FCFF!$B$9+FCFF!$I$9*(1+Inputs!$B$6)/($B$4-Inputs!$B$6)/(1+$B$4)^7} -> -1465.1111 | C11: {=NPV($D$4,FCFF!$C$9:$I$9)+FCFF!$B$9+FCFF!$I$9*(1+Inputs!$B$6)/($D$4-Inputs!$B$6)/(1+$D$4)^7} -> -1870.5878 | D11: =ABS(C11-B11) -> 405.4767
A12: g | B12: {=NPV(Inputs!$B$33,FCFF!$C$9:$I$9)+FCFF!$B$9+FCFF!$I$9*(1+$B$5)/(Inputs!$B$33-$B$5)/(1+Inputs!$B$33)^7} -> -1758.0066 | C12: {=NPV(Inputs!$B$33,FCFF!$C$9:$I$9)+FCFF!$B$9+FCFF!$I$9*(1+$D$5)/(Inputs!$B$33-$D$5)/(1+Inputs!$B$33)^7} -> -1620.653 | D12: =ABS(C12-B12) -> 137.35366
A13: Rev Scale | B13: {=NPV(Inputs!$B$33,C15:I15)+B15+INDEX(B15:I15,1,8)*(1+Inputs!$B$6)/(Inputs!$B$33-Inputs!$B$6)/(1+Inputs!$B$33)^7} -> -1523.9087 | C13: {=NPV(Inputs!$B$33,C16:I16)+B16+INDEX(B16:I16,1,8)*(1+Inputs!$B$6)/(Inputs!$B$33-Inputs!$B$6)/(1+Inputs!$B$33)^7} -> -1862.5551 | D13: =ABS(C13-B13) -> 338.64638
A15: Rev Low FCFF | B15: =FCFF!B9*$B$6 -> -2250 | C15: =FCFF!C9*$B$6 -> -251.025 | D15: =FCFF!D9*$B$6 -> -186.9 | E15: =FCFF!E9*$B$6 -> -87.4185 | F15: =FCFF!F9*$B$6 -> -51.793148 | G15: =FCFF!G9*$B$6 -> 76.497285 | H15: =FCFF!H9*$B$6 -> 134.09983 | I15: =FCFF!I9*$B$6 -> 181.3906
A16: Rev High FCFF | B16: =FCFF!B9*$D$6 -> -2750 | C16: =FCFF!C9*$D$6 -> -306.80833 | D16: =FCFF!D9*$D$6 -> -228.43333 | E16: =FCFF!E9*$D$6 -> -106.84483 | F16: =FCFF!F9*$D$6 -> -63.302736 | G16: =FCFF!G9*$D$6 -> 93.496682 | H16: =FCFF!H9*$D$6 -> 163.89979 | I16: =FCFF!I9*$D$6 -> 221.69962

Sheet Leverage_Analysis
A1: Metric | B1: FY2019 | C1: FY2020 | D1: FY2021 | E1: FY2022 | F1: FY2023 | G1: FY2024
A2: Total Debt | B2: 5685 | C2: 7330 | D2: 7776 | E2: 5955 | F2: 5759 | G2: 5132
A3: Total Equity | B3: -3354 | C3: -4875 | D3: -4636 | E3: -6016 | F3: -3629 | G3: -881
A4: Cash & Cash Equivalents | B4: 4443 | C4: 3452 | D4: 2621 | E4: 2607 | F4: 3784 | G4: 5575
A5: Net Debt | B5: 1242 | C5: 3878 | D5: 5155 | E5: 3348 | F5: 1975 | G5: -443
A6: Short-Term Debt | B6: — | C6: — | D6: — | E6: — | F6: — | G6: 1097
A7: Long-Term Debt | B7: — | C7: — | D7: — | E7: — | F7: — | G7: 4035
A8: Debt/Equity | B8: N/A (neg) | C8: N/A (neg) | D8: N/A (neg) | E8: N/A (neg) | F8: N/A (neg) | G8: N/A (neg)
A9: Total Debt / Total Assets | B9: 17.6192 | C9: 24.8331 | D9: 27.1186 | E9: 20.2207 | F9: 18.2756 | G9: 14.381
A10: EBITDA / Interest Expense | B10: 1.3296 | C10: 1.1627 | D10: 4.6889 | E10: 4.3625 | F10: 6.1674 | G10: 7.6382
A11: EBIT / Interest Expense | B11: -3.5407 | C11: -8.5794 | D11: 1.4857 | E11: 1.9197 | F11: 3.9009 | G11: 6.1438
A14: Metric | B14: Rolls-Royce | C14: Safran (FR) | D14: GE Aero (US) | E14: Industry Avg.
A15: Solvency
A16: Debt / Assets | B16: 0.144 | C16: 0.087 | D16: 0.16 | E16: 0.537
A17: Debt / Equity | B17: N/A (Neg. Eq) | C17: 0.499 | D17: 1.05 | E17: 0.54
A18: Coverage
A19: EBITDA / Interest | B19: 7.6x | C19: 34.5x | D19: 15.0x | E19: 12.0x
A20: EBIT / Interest | B20: 6.1x | C20: 26.2x | D20: 12.3x | E20: 8.7x
A21: Liquidity
A22: Net Debt position | B22: Net Cash (-£443m) | C22: Net Cash (-£1.5bn) | D22: Net Debt (£4.5bn) | E22: —
A23: Structure
A24: Long-Term Debt % | B24: 0.79 | C24: 0.85 | D24: 0.82 | E24: 0.8

Sheet Appendix
B2: Financial Charts

Sheet Additional
B2: (All monetary values in £ millions unless otherwise stated)
B4: Metric | C4: 2019 | D4: 2020 | E4: 2021 | F4: 2022 | G4: 2023 | H4: 2024
B5: Total Debt | C5: 5685 | D5: 7330 | E5: 7776 | F5: 5955 | G5: 5759 | H5: 5132
B6: Short-Term Debt | C6: 775 | D6: 1272 | E6: 279 | F6: 358 | G6: 809 | H6: 1097
B7: Long-Term Debt | C7: 4910 | D7: 6058 | E7: 7497 | F7: 5597 | G7: 4950 | H7: 4035
B8: Cash & Cash Equivalents | C8: 4443 | D8: 3452 | E8: 2621 | F8: 2607 | G8: 3784 | H8: 5575
B9: Net Debt | C9: 1242 | D9: 3878 | E9: 5155 | F9: 3348 | G9: 1975 | H9: -443
B10: Total Shareholders’ Equity | C10: -3354 | D10: -4875 | E10: -4636 | F10: -6016 | G10: -3629 | H10: -881
B11: Debt-to-Assets (%) | C11: 17.6192 | D11: 24.8331 | E11: 27.1186 | F11: 20.2207 | G11: 18.2756 | H11: 14.381
B12: Debt-to-Equity | C12: N/A | D12: N/A | E12: N/A | F12: N/A | G12: N/A | H12: N/A
B13: EBITDA | C13: 359 | D13: 293 | E13: 1477 | F13: 1793 | G13: 2800 | H13: 3399
B14: Net Debt/EBITDA | C14: 3.4429 | D14: 13.2355 | E14: 3.4848 | F14: 1.8611 | G14: 0.7054 | H14: -0.1303
